Workbook
Name Slicer_Category: #N/A
Name Slicer_Customer_Segment: #N/A
Name Slicer_Payment_Method: #N/A
Name Slicer_Region: #N/A
Name Slicer_Year: #N/A

Sheet Dashboard
A1: Flipkart E-Commerce Sales Analytics Dashboard
A2: Overall Business Performance
A4: TOTAL SALES | D4: TOTAL PROFIT | G4: TOTAL ORDERS | J4: TOTAL QUANTITY | M4: AVERAGE ORDER VALUE | P4: PROFIT MARGIN
A5: =Calculations!B4 -> 75213113 | D5: =Calculations!B5 -> 15042623 | G5: =Calculations!B6 -> 1000 | J5: =Calculations!B7 -> 3097 | M5: =Calculations!B8 -> 75213.113 | P5: =Calculations!B10 -> 0.2

Sheet Pivot_Analysis
A1: Row Labels | B1: Count of Order ID | C1: Sum of Total Sales (INR) | D1: Sum of Profit (INR) | F1: Row Labels | G1: Sum of Total Sales (INR) | H1: Sum of Profit (INR) | I1: Sum of Quantity Sold | K1: Row Labels | L1: Sum of Total Sales (INR)
A2: 1 | B2: 14 | C2: 740312.83 | D2: 148062.57 | F2: Educational Book | G2: 4522055.3 | H2: 904411.07 | I2: 188 | K2: Educational Book | L2: 4522055.3 | N2: Row Labels | O2: Sum of Total Sales (INR)
A3: 1.1 | B3: 34 | C3: 2606467 | D3: 521293.39 | F3: Laptop | G3: 4132783.7 | H3: 826556.74 | I3: 156 | K3: Laptop | L3: 4132783.7 | N3: Wallet | O3: 13446764
A4: 1.2 | B4: 25 | C4: 2366120.2 | D4: 473224.04 | F4: Table Lamp | G4: 3986691.7 | H4: 797338.34 | I4: 141 | K4: Table Lamp | L4: 3986691.7 | N4: Net Banking | O4: 13219948
A5: 1.3 | B5: 17 | C5: 1421794.4 | D5: 284358.89 | F5: Headphones | G5: 3722765.3 | H5: 744553.05 | I5: 135 | K5: Headphones | L5: 3722765.3 | N5: UPI | O5: 12790919
A6: 1.4 | B6: 22 | C6: 1921657.5 | D6: 384331.5 | F6: Jeans | G6: 3685259.6 | H6: 737051.92 | I6: 132 | K6: Jeans | L6: 3685259.6 | N6: COD | O6: 12457137
A7: 1.5 | B7: 27 | C7: 1334178.2 | D7: 266835.65 | F7: Smartwatch | G7: 3680177.8 | H7: 736035.56 | I7: 137 | K7: Smartwatch | L7: 3680177.8 | N7: Debit Card | O7: 12142559
A8: 1.6 | B8: 26 | C8: 1811803.2 | D8: 362360.64 | F8: Face Cream | G8: 3646817 | H8: 729363.39 | I8: 124 | K8: Face Cream | L8: 3646817 | N8: Credit Card | O8: 11155786
A9: 1.7 | B9: 17 | C9: 1437245.2 | D9: 287449.05 | F9: Perfume | G9: 3266905.7 | H9: 653381.15 | I9: 125 | K9: Perfume | L9: 3266905.7 | N9: Grand Total | O9: 75213113
A10: 1.8 | B10: 26 | C10: 2374539.8 | D10: 474907.96 | F10: Fiction Novel | G10: 3172999.9 | H10: 634599.98 | I10: 138 | K10: Fiction Novel | L10: 3172999.9
A11: 1.9 | B11: 30 | C11: 2134105.2 | D11: 426821.04 | F11: Jacket | G11: 3161049 | H11: 632209.81 | I11: 121 | K11: Jacket | L11: 3161049
A12: 2 | B12: 31 | C12: 1706829.5 | D12: 341365.9 | F12: T-Shirt | G12: 2907013.3 | H12: 581402.66 | I12: 131 | K12: Grand Total | L12: 36977505 | N12: Row Labels | O12: Sum of Total Sales (INR)
A13: 2.1 | B13: 20 | C13: 1286614.5 | D13: 257322.89 | F13: Tablet | G13: 2895523.5 | H13: 579104.69 | I13: 122 | N13: Beauty | O13: 14680584
A14: 2.2 | B14: 15 | C14: 997459.03 | D14: 199491.81 | F14: Sneakers | G14: 2883135 | H14: 576626.99 | I14: 125 | K14: Row Labels | L14: Sum of Total Sales (INR) | M14: Sum of Profit (INR) | N14: Books | O14: 14785760
A15: 2.3 | B15: 21 | C15: 1518213.8 | D15: 303642.76 | F15: Smartphone | G15: 2875922.8 | H15: 575184.57 | I15: 123 | K15: 45323 | L15: 3910477 | M15: 782095.4 | N15: Clothing | O15: 15114387
A16: 2.4 | B16: 22 | C16: 2055263.2 | D16: 411052.64 | F16: Lipstick | G16: 2844209.1 | H16: 568841.82 | I16: 134 | K16: 45352 | L16: 6508879 | M16: 1301775.8 | N16: Electronics | O16: 17307173
A17: 2.5 | B17: 28 | C17: 2138039.2 | D17: 427607.84 | F17: Sofa Cover | G17: 2666946.1 | H17: 533389.22 | I17: 118 | K17: 45383 | L17: 7334962.9 | M17: 1466992.6 | N17: Home & Kitchen | O17: 13325209
A18: 2.6 | B18: 19 | C18: 1733734.9 | D18: 346746.98 | F18: Self-Help Book | G18: 2638065.2 | H18: 527613.04 | I18: 115 | K18: 45413 | L18: 6706005 | M18: 1341201 | N18: Grand Total | O18: 75213113
A19: 2.7 | B19: 28 | C19: 2320094.8 | D19: 464018.96 | F19: Cookbook | G19: 2514179.2 | H19: 502835.84 | I19: 92 | K19: 45444 | L19: 4992364.8 | M19: 998472.95
A20: 2.8 | B20: 18 | C20: 1022397.4 | D20: 204479.48 | F20: Hair Dryer | G20: 2505130.7 | H20: 501026.13 | I20: 108 | K20: 45474 | L20: 7637325 | M20: 1527465
A21: 2.9 | B21: 29 | C21: 2513863.4 | D21: 502772.67 | F21: Cookware Set | G21: 2490551.4 | H21: 498110.29 | I21: 120 | K21: 45505 | L21: 5418894 | M21: 1083778.8
A22: 3 | B22: 29 | C22: 2381518.2 | D22: 476303.64 | F22: Dress | G22: 2477929.9 | H22: 495585.99 | I22: 100 | K22: 45536 | L22: 6264222.3 | M22: 1252844.5
A23: 3.1 | B23: 27 | C23: 2216895.2 | D23: 443379.03 | F23: Shampoo | G23: 2417521.6 | H23: 483504.32 | I23: 92 | K23: 45566 | L23: 5702923.4 | M23: 1140584.7
A24: 3.2 | B24: 24 | C24: 1749134.6 | D24: 349826.91 | F24: Mixer Grinder | G24: 2297176.6 | H24: 459435.32 | I24: 111 | K24: 45597 | L24: 5578535.1 | M24: 1115707
A25: 3.3 | B25: 21 | C25: 1725686.4 | D25: 345137.28 | F25: Comic Book | G25: 1938460 | H25: 387692 | I25: 120 | K25: 45627 | L25: 6491640 | M25: 1298328
A26: 3.4 | B26: 19 | C26: 1447231.8 | D26: 289446.36 | F26: Bedsheet | G26: 1883843.3 | H26: 376768.66 | I26: 89 | K26: 45658 | L26: 7160788.2 | M26: 1432157.6
A27: 3.5 | B27: 35 | C27: 2208088.2 | D27: 441617.65 | F27: Grand Total | G27: 75213113 | H27: 15042623 | I27: 3097 | K27: 45689 | L27: 1506096.2 | M27: 301219.24
A28: 3.6 | B28: 28 | C28: 1694850.8 | D28: 338970.16 | K28: Grand Total | L28: 75213113 | M28: 15042623
A29: 3.7 | B29: 27 | C29: 2451176 | D29: 490235.2
A30: 3.8 | B30: 27 | C30: 1605414.1 | D30: 321082.83 | F30: Sum of Total Sales (INR) | G30: Column Labels | N30: Row Labels | O30: Sum of Total Sales (INR)
A31: 3.9 | B31: 22 | C31: 1567369.4 | D31: 313473.88 | F31: Row Labels | G31: Beauty | H31: Books | I31: Clothing | J31: Electronics | K31: Home & Kitchen | L31: Grand Total | N31: Wholesale | O31: 25732036
A32: 4 | B32: 34 | C32: 2844144.5 | D32: 568828.89 | F32: East | G32: 3449210.3 | H32: 3196018.1 | I32: 3722966.8 | J32: 3363473.8 | K32: 2936175.2 | L32: 16667844 | N32: Online | O32: 25169884
A33: 4.1 | B33: 28 | C33: 2644986.8 | D33: 528997.36 | F33: North | G33: 3690523.3 | H33: 4173438.3 | I33: 3438004.6 | J33: 4520019.8 | K33: 4468005.8 | L33: 20289992 | N33: Retail | O33: 24311193
A34: 4.2 | B34: 35 | C34: 2430088.5 | D34: 486017.71 | F34: South | G34: 4208861.5 | H34: 3859061.3 | I34: 3687686 | J34: 4931243.5 | K34: 3175656.4 | L34: 19862509 | N34: Grand Total | O34: 75213113
A35: 4.3 | B35: 25 | C35: 1629153.2 | D35: 325830.63 | F35: West | G35: 3331989 | H35: 3557241.9 | I35: 4265729.4 | J35: 4492436 | K35: 2745371.6 | L35: 18392768
A36: 4.4 | B36: 32 | C36: 2826990.4 | D36: 565398.08 | F36: Grand Total | G36: 14680584 | H36: 14785760 | I36: 15114387 | J36: 17307173 | K36: 13325209 | L36: 75213113
A37: 4.5 | B37: 25 | C37: 1670650.5 | D37: 334130.1
A38: 4.6 | B38: 26 | C38: 1730116.7 | D38: 346023.33
A39: 4.7 | B39: 17 | C39: 1429808.3 | D39: 285961.67 | F39: Sum of Total Sales (INR) | G39: Column Labels | L39: Row Labels | M39: Sum of Total Sales (INR)
A40: 4.8 | B40: 22 | C40: 1797622.2 | D40: 359524.44 | F40: Row Labels | G40: Online | H40: Retail | I40: Wholesale | J40: Grand Total | L40: North | M40: 20289992
...

Sheet Calculations
A1: Flipkart E-Commerce Sales Analytics
A2: Overall Business Performance
A3: KPI | B3: Value | D3: Metric | E3: Value
A4: Total Sales | B4: =SUM(Cleaned_Data!F2:F1001) -> 75213113 | D4: Minimum Order Date | E4: =MIN(Cleaned_Data!G2:G1001) -> 45334
A5: Total Profit | B5: =SUM(Cleaned_Data!L2:L1001) -> 15042623 | D5: Maximum Order Date | E5: =MAX(Cleaned_Data!G2:G1001) -> 45697
A6: Total Orders | B6: =COUNTA(Cleaned_Data!A2:A1001) -> 1000 | D6: Minimum Rating | E6: =MIN(Cleaned_Data!I2:I1001) -> 1
A7: Total Quantity Sold | B7: =SUM(Cleaned_Data!E2:E1001) -> 3097 | D7: Maximum Rating | E7: =MAX(Cleaned_Data!I2:I1001) -> 5
A8: Average Order Value | B8: =B4/B6 -> 75213.113 | D8: Minimum Discount | E8: =MIN(Cleaned_Data!M2:M1001) -> 5
A9: Average Customer Rating | B9: =AVERAGE(Cleaned_Data!I2:I1001) -> 3.0111 | D9: Maximum Discount | E9: =MAX(Cleaned_Data!M2:M1001) -> 30
A10: Profit Margin % | B10: =B5/B4 -> 0.2 | D10: Minimum Profit | E10: =MIN(Cleaned_Data!L2:L1001) -> 83.91
A11: Average Discount % | B11: =AVERAGE(Cleaned_Data!M2:M1001) -> 17.699 | D11: Maximum Profit | E11: =MAX(Cleaned_Data!L2:L1001) -> 48780.78

Sheet Data_Quality
A1: Metric | B1: Result | C1: Status
A2: Total Records | B2: 1000 | C2: ✅
A3: Unique Orders | B3: 1000 | C3: ✅
A4: Missing Values | B4: 0 | C4: ✅
A5: Duplicate Orders | B5: 0 | C5: ✅
A6: Date Validity | B6: Valid | C6: ✅
A7: Rating Range | B7: Valid | C7: ✅
A8: Quantity Range | B8: Valid | C8: ✅

Sheet Cleaned_Data
A1: Order ID | B1: Product Name | C1: Category | D1: Price (INR) | E1: Quantity Sold | F1: Total Sales (INR) | G1: Order Date | H1: Payment Method | I1: Customer Rating | J1: Month | K1: Year | L1: Profit (INR) | M1: Discount % | N1: Customer Segment | O1: Region | P1: Calculated Sales | Q1: Sales Difference | R1: Profit Margin % | S1: Revenue per Unit | T1: Profit per Unit | U1: Month Number | V1: Quarter | W1: Year-Month | X1: Discount Amount | Y1: Net Sales After Discount | Z1: Month Start
A2: ORD00001 | B2: Educational Book | C2: Books | D2: 49069.56 | E2: 2 | F2: 98139.12 | G2: 45547 | H2: Debit Card | I2: 3.5 | J2: September | K2: 2024 | L2: 19627.824 | M2: 11 | N2: Online | O2: West | P2: =FlipkartSales[[#This Row],[Price (INR)]]*FlipkartSales[[#This Row],[Quantity Sold]] -> 98139.12 | Q2: =FlipkartSales[[#This Row],[Total Sales (INR)]]-FlipkartSales[[#This Row],[Calculated Sales]] -> 0 | R2: =L2/F2 -> 0.2 | S2: =F2/E2 -> 49069.56 | T2: =L2/E2 -> 9813.912 | U2: =MONTH(G2) -> 9 | V2: ="Q"&ROUNDUP(MONTH(G2)/3,0) -> Q3 | W2: =TEXT(G2,"mmm-yyyy") -> Sep-2024 | X2: =F2*M2/100 -> 10795.303 | Y2: =F2-X2 -> 87343.817 | Z2: =DATE(K2,MATCH(J2,{"January","February","March","April","May","June","July","August","September","October","November","December"},0),1) -> 45536
A3: ORD00002 | B3: Jeans | C3: Clothing | D3: 12755.85 | E3: 4 | F3: 51023.4 | G3: 45644 | H3: UPI | I3: 3.9 | J3: December | K3: 2024 | L3: 10204.68 | M3: 24 | N3: Wholesale | O3: North | P3: =FlipkartSales[[#This Row],[Price (INR)]]*FlipkartSales[[#This Row],[Quantity Sold]] -> 51023.4 | Q3: =FlipkartSales[[#This Row],[Total Sales (INR)]]-FlipkartSales[[#This Row],[Calculated Sales]] -> 0 | R3: =L3/F3 -> 0.2 | S3: =F3/E3 -> 12755.85 | T3: =L3/E3 -> 2551.17 | U3: =MONTH(G3) -> 12 | V3: ="Q"&ROUNDUP(MONTH(G3)/3,0) -> Q4 | W3: =TEXT(G3,"mmm-yyyy") -> Dec-2024 | X3: =F3*M3/100 -> 12245.616 | Y3: =F3-X3 -> 38777.784 | Z3: =DATE(K3,MATCH(J3,{"January","February","March","April","May","June","July","August","September","October","November","December"},0),1) -> 45627
A4: ORD00003 | B4: Face Cream | C4: Beauty | D4: 11092.19 | E4: 4 | F4: 44368.76 | G4: 45430 | H4: Debit Card | I4: 4.4 | J4: May | K4: 2024 | L4: 8873.752 | M4: 19 | N4: Online | O4: South | P4: =FlipkartSales[[#This Row],[Price (INR)]]*FlipkartSales[[#This Row],[Quantity Sold]] -> 44368.76 | Q4: =FlipkartSales[[#This Row],[Total Sales (INR)]]-FlipkartSales[[#This Row],[Calculated Sales]] -> 0 | R4: =L4/F4 -> 0.2 | S4: =F4/E4 -> 11092.19 | T4: =L4/E4 -> 2218.438 | U4: =MONTH(G4) -> 5 | V4: ="Q"&ROUNDUP(MONTH(G4)/3,0) -> Q2 | W4: =TEXT(G4,"mmm-yyyy") -> May-2024 | X4: =F4*M4/100 -> 8430.0644 | Y4: =F4-X4 -> 35938.696 | Z4: =DATE(K4,MATCH(J4,{"January","February","March","April","May","June","July","August","September","October","November","December"},0),1) -> 45413
A5: ORD00004 | B5: Smartwatch | C5: Electronics | D5: 32657.81 | E5: 1 | F5: 32657.81 | G5: 45604 | H5: Debit Card | I5: 3.2 | J5: November | K5: 2024 | L5: 6531.562 | M5: 15 | N5: Online | O5: North | P5: =FlipkartSales[[#This Row],[Price (INR)]]*FlipkartSales[[#This Row],[Quantity Sold]] -> 32657.81 | Q5: =FlipkartSales[[#This Row],[Total Sales (INR)]]-FlipkartSales[[#This Row],[Calculated Sales]] -> 0 | R5: =L5/F5 -> 0.2 | S5: =F5/E5 -> 32657.81 | T5: =L5/E5 -> 6531.562 | U5: =MONTH(G5) -> 11 | V5: ="Q"&ROUNDUP(MONTH(G5)/3,0) -> Q4 | W5: =TEXT(G5,"mmm-yyyy") -> Nov-2024 | X5: =F5*M5/100 -> 4898.6715 | Y5: =F5-X5 -> 27759.139 | Z5: =DATE(K5,MATCH(J5,{"January","February","March","April","May","June","July","August","September","October","November","December"},0),1) -> 45597
A6: ORD00005 | B6: Cookware Set | C6: Home & Kitchen | D6: 26590.08 | E6: 3 | F6: 79770.24 | G6: 45653 | H6: UPI | I6: 3.1 | J6: December | K6: 2024 | L6: 15954.048 | M6: 12 | N6: Retail | O6: North | P6: =FlipkartSales[[#This Row],[Price (INR)]]*FlipkartSales[[#This Row],[Quantity Sold]] -> 79770.24 | Q6: =FlipkartSales[[#This Row],[Total Sales (INR)]]-FlipkartSales[[#This Row],[Calculated Sales]] -> 0 | R6: =L6/F6 -> 0.2 | S6: =F6/E6 -> 26590.08 | T6: =L6/E6 -> 5318.016 | U6: =MONTH(G6) -> 12 | V6: ="Q"&ROUNDUP(MONTH(G6)/3,0) -> Q4 | W6: =TEXT(G6,"mmm-yyyy") -> Dec-2024 | X6: =F6*M6/100 -> 9572.4288 | Y6: =F6-X6 -> 70197.811 | Z6: =DATE(K6,MATCH(J6,{"January","February","March","April","May","June","July","August","September","October","November","December"},0),1) -> 45627
A7: ORD00006 | B7: Mixer Grinder | C7: Home & Kitchen | D7: 10475.03 | E7: 2 | F7: 20950.06 | G7: 45587 | H7: Wallet | I7: 1.7 | J7: October | K7: 2024 | L7: 4190.012 | M7: 25 | N7: Wholesale | O7: North | P7: =FlipkartSales[[#This Row],[Price (INR)]]*FlipkartSales[[#This Row],[Quantity Sold]] -> 20950.06 | Q7: =FlipkartSales[[#This Row],[Total Sales (INR)]]-FlipkartSales[[#This Row],[Calculated Sales]] -> 0 | R7: =L7/F7 -> 0.2 | S7: =F7/E7 -> 10475.03 | T7: =L7/E7 -> 2095.006 | U7: =MONTH(G7) -> 10 | V7: ="Q"&ROUNDUP(MONTH(G7)/3,0) -> Q4 | W7: =TEXT(G7,"mmm-yyyy") -> Oct-2024 | X7: =F7*M7/100 -> 5237.515 | Y7: =F7-X7 -> 15712.545 | Z7: =DATE(K7,MATCH(J7,{"January","February","March","April","May","June","July","August","September","October","November","December"},0),1) -> 45566
A8: ORD00007 | B8: Sneakers | C8: Clothing | D8: 38647.72 | E8: 3 | F8: 115943.16 | G8: 45477 | H8: Wallet | I8: 2 | J8: July | K8: 2024 | L8: 23188.632 | M8: 11 | N8: Wholesale | O8: North | P8: =FlipkartSales[[#This Row],[Price (INR)]]*FlipkartSales[[#This Row],[Quantity Sold]] -> 115943.16 | Q8: =FlipkartSales[[#This Row],[Total Sales (INR)]]-FlipkartSales[[#This Row],[Calculated Sales]] -> 0 | R8: =L8/F8 -> 0.2 | S8: =F8/E8 -> 38647.72 | T8: =L8/E8 -> 7729.544 | U8: =MONTH(G8) -> 7 | V8: ="Q"&ROUNDUP(MONTH(G8)/3,0) -> Q3 | W8: =TEXT(G8,"mmm-yyyy") -> Jul-2024 | X8: =F8*M8/100 -> 12753.748 | Y8: =F8-X8 -> 103189.41 | Z8: =DATE(K8,MATCH(J8,{"January","February","March","April","May","June","July","August","September","October","November","December"},0),1) -> 45474
A9: ORD00008 | B9: Table Lamp | C9: Home & Kitchen | D9: 24818.59 | E9: 3 | F9: 74455.77 | G9: 45653 | H9: Debit Card | I9: 2.4 | J9: December | K9: 2024 | L9: 14891.154 | M9: 30 | N9: Wholesale | O9: South | P9: =FlipkartSales[[#This Row],[Price (INR)]]*FlipkartSales[[#This Row],[Quantity Sold]] -> 74455.77 | Q9: =FlipkartSales[[#This Row],[Total Sales (INR)]]-FlipkartSales[[#This Row],[Calculated Sales]] -> 0 | R9: =L9/F9 -> 0.2 | S9: =F9/E9 -> 24818.59 | T9: =L9/E9 -> 4963.718 | U9: =MONTH(G9) -> 12 | V9: ="Q"&ROUNDUP(MONTH(G9)/3,0) -> Q4 | W9: =TEXT(G9,"mmm-yyyy") -> Dec-2024 | X9: =F9*M9/100 -> 22336.731 | Y9: =F9-X9 -> 52119.039 | Z9: =DATE(K9,MATCH(J9,{"January","February","March","April","May","June","July","August","September","October","November","December"},0),1) -> 45627
A10: ORD00009 | B10: Jacket | C10: Clothing | D10: 1987.39 | E10: 2 | F10: 3974.78 | G10: 45675 | H10: Debit Card | I10: 2.6 | J10: January | K10: 2025 | L10: 794.956 | M10: 23 | N10: Online | O10: North | P10: =FlipkartSales[[#This Row],[Price (INR)]]*FlipkartSales[[#This Row],[Quantity Sold]] -> 3974.78 | Q10: =FlipkartSales[[#This Row],[Total Sales (INR)]]-FlipkartSales[[#This Row],[Calculated Sales]] -> 0 | R10: =L10/F10 -> 0.2 | S10: =F10/E10 -> 1987.39 | T10: =L10/E10 -> 397.478 | U10: =MONTH(G10) -> 1 | V10: ="Q"&ROUNDUP(MONTH(G10)/3,0) -> Q1 | W10: =TEXT(G10,"mmm-yyyy") -> Jan-2025 | X10: =F10*M10/100 -> 914.1994 | Y10: =F10-X10 -> 3060.5806 | Z10: =DATE(K10,MATCH(J10,{"January","February","March","April","May","June","July","August","September","October","November","December"},0),1) -> 45658
A11: ORD00010 | B11: Tablet | C11: Electronics | D11: 26876.51 | E11: 2 | F11: 53753.02 | G11: 45365 | H11: Debit Card | I11: 4 | J11: March | K11: 2024 | L11: 10750.604 | M11: 27 | N11: Online | O11: North | P11: =FlipkartSales[[#This Row],[Price (INR)]]*FlipkartSales[[#This Row],[Quantity Sold]] -> 53753.02 | Q11: =FlipkartSales[[#This Row],[Total Sales (INR)]]-FlipkartSales[[#This Row],[Calculated Sales]] -> 0 | R11: =L11/F11 -> 0.2 | S11: =F11/E11 -> 26876.51 | T11: =L11/E11 -> 5375.302 | U11: =MONTH(G11) -> 3 | V11: ="Q"&ROUNDUP(MONTH(G11)/3,0) -> Q1 | W11: =TEXT(G11,"mmm-yyyy") -> Mar-2024 | X11: =F11*M11/100 -> 14513.315 | Y11: =F11-X11 -> 39239.705 | Z11: =DATE(K11,MATCH(J11,{"January","February","March","April","May","June","July","August","September","October","November","December"},0),1) -> 45352
A12: ORD00011 | B12: Perfume | C12: Beauty | D12: 46409.57 | E12: 5 | F12: 232047.85 | G12: 45696 | H12: UPI | I12: 2.3 | J12: February | K12: 2025 | L12: 46409.57 | M12: 15 | N12: Online | O12: West | P12: =FlipkartSales[[#This Row],[Price (INR)]]*FlipkartSales[[#This Row],[Quantity Sold]] -> 232047.85 | Q12: =FlipkartSales[[#This Row],[Total Sales (INR)]]-FlipkartSales[[#This Row],[Calculated Sales]] -> 0 | R12: =L12/F12 -> 0.2 | S12: =F12/E12 -> 46409.57 | T12: =L12/E12 -> 9281.914 | U12: =MONTH(G12) -> 2 | V12: ="Q"&ROUNDUP(MONTH(G12)/3,0) -> Q1 | W12: =TEXT(G12,"mmm-yyyy") -> Feb-2025 | X12: =F12*M12/100 -> 34807.177 | Y12: =F12-X12 -> 197240.67 | Z12: =DATE(K12,MATCH(J12,{"January","February","March","April","May","June","July","August","September","October","November","December"},0),1) -> 45689
A13: ORD00012 | B13: Lipstick | C13: Beauty | D13: 48780.78 | E13: 5 | F13: 243903.9 | G13: 45395 | H13: UPI | I13: 1.3 | J13: April | K13: 2024 | L13: 48780.78 | M13: 15 | N13: Retail | O13: South | P13: =FlipkartSales[[#This Row],[Price (INR)]]*FlipkartSales[[#This Row],[Quantity Sold]] -> 243903.9 | Q13: =FlipkartSales[[#This Row],[Total Sales (INR)]]-FlipkartSales[[#This Row],[Calculated Sales]] -> 0 | R13: =L13/F13 -> 0.2 | S13: =F13/E13 -> 48780.78 | T13: =L13/E13 -> 9756.156 | U13: =MONTH(G13) -> 4 | V13: ="Q"&ROUNDUP(MONTH(G13)/3,0) -> Q2 | W13: =TEXT(G13,"mmm-yyyy") -> Apr-2024 | X13: =F13*M13/100 -> 36585.585 | Y13: =F13-X13 -> 207318.32 | Z13: =DATE(K13,MATCH(J13,{"January","February","March","April","May","June","July","August","September","October","November","December"},0),1) -> 45383
... A1001: ORD01000 | B1001: Table Lamp | C1001: Home & Kitchen | D1001: 16698.12 | E1001: 4 | F1001: 66792.48 | G1001: 45377 | H1001: Credit Card | I1001: 1.6 | J1001: March | K1001: 2024 | L1001: 13358.496 | M1001: 19 | N1001: Wholesale | O1001: East | P1001: =FlipkartSales[[#This Row],[Price (INR)]]*FlipkartSales[[#This Row],[Quantity Sold]] -> 66792.48 | Q1001: =FlipkartSales[[#This Row],[Total Sales (INR)]]-FlipkartSales[[#This Row],[Calculated Sales]] -> 0 | R1001: =L1001/F1001 -> 0.2 | S1001: =F1001/E1001 -> 16698.12 | T1001: =L1001/E1001 -> 3339.624 | U1001: =MONTH(G1001) -> 3 | V1001: ="Q"&ROUNDUP(MONTH(G1001)/3,0) -> Q1 | W1001: =TEXT(G1001,"mmm-yyyy") -> Mar-2024 | X1001: =F1001*M1001/100 -> 12690.571 | Y1001: =F1001-X1001 -> 54101.909 | Z1001: =DATE(K1001,MATCH(J1001,{"January","February","March","April","May","June","July","August","September","October","November","December"},0),1) -> 45352

Sheet Raw_Data
A1: Order ID | B1: Product Name | C1: Category | D1: Price (INR) | E1: Quantity Sold | F1: Total Sales (INR) | G1: Order Date | H1: Payment Method | I1: Customer Rating | J1: Month | K1: Year | L1: Profit (INR) | M1: Discount % | N1: Customer Segment | O1: Region
A2: ORD00001 | B2: Educational Book | C2: Books | D2: 49069.56 | E2: 2 | F2: 98139.12 | G2: 45547 | H2: Debit Card | I2: 3.5 | J2: September | K2: 2024 | L2: 19627.824 | M2: 11 | N2: Online | O2: West
A3: ORD00002 | B3: Jeans | C3: Clothing | D3: 12755.85 | E3: 4 | F3: 51023.4 | G3: 45644 | H3: UPI | I3: 3.9 | J3: December | K3: 2024 | L3: 10204.68 | M3: 24 | N3: Wholesale | O3: North
A4: ORD00003 | B4: Face Cream | C4: Beauty | D4: 11092.19 | E4: 4 | F4: 44368.76 | G4: 45430 | H4: Debit Card | I4: 4.4 | J4: May | K4: 2024 | L4: 8873.752 | M4: 19 | N4: Online | O4: South
A5: ORD00004 | B5: Smartwatch | C5: Electronics | D5: 32657.81 | E5: 1 | F5: 32657.81 | G5: 45604 | H5: Debit Card | I5: 3.2 | J5: November | K5: 2024 | L5: 6531.562 | M5: 15 | N5: Online | O5: North
A6: ORD00005 | B6: Cookware Set | C6: Home & Kitchen | D6: 26590.08 | E6: 3 | F6: 79770.24 | G6: 45653 | H6: UPI | I6: 3.1 | J6: December | K6: 2024 | L6: 15954.048 | M6: 12 | N6: Retail | O6: North
A7: ORD00006 | B7: Mixer Grinder | C7: Home & Kitchen | D7: 10475.03 | E7: 2 | F7: 20950.06 | G7: 45587 | H7: Wallet | I7: 1.7 | J7: October | K7: 2024 | L7: 4190.012 | M7: 25 | N7: Wholesale | O7: North
A8: ORD00007 | B8: Sneakers | C8: Clothing | D8: 38647.72 | E8: 3 | F8: 115943.16 | G8: 45477 | H8: Wallet | I8: 2 | J8: July | K8: 2024 | L8: 23188.632 | M8: 11 | N8: Wholesale | O8: North
A9: ORD00008 | B9: Table Lamp | C9: Home & Kitchen | D9: 24818.59 | E9: 3 | F9: 74455.77 | G9: 45653 | H9: Debit Card | I9: 2.4 | J9: December | K9: 2024 | L9: 14891.154 | M9: 30 | N9: Wholesale | O9: South
A10: ORD00009 | B10: Jacket | C10: Clothing | D10: 1987.39 | E10: 2 | F10: 3974.78 | G10: 45675 | H10: Debit Card | I10: 2.6 | J10: January | K10: 2025 | L10: 794.956 | M10: 23 | N10: Online | O10: North
A11: ORD00010 | B11: Tablet | C11: Electronics | D11: 26876.51 | E11: 2 | F11: 53753.02 | G11: 45365 | H11: Debit Card | I11: 4 | J11: March | K11: 2024 | L11: 10750.604 | M11: 27 | N11: Online | O11: North
A12: ORD00011 | B12: Perfume | C12: Beauty | D12: 46409.57 | E12: 5 | F12: 232047.85 | G12: 45696 | H12: UPI | I12: 2.3 | J12: February | K12: 2025 | L12: 46409.57 | M12: 15 | N12: Online | O12: West
A13: ORD00012 | B13: Lipstick | C13: Beauty | D13: 48780.78 | E13: 5 | F13: 243903.9 | G13: 45395 | H13: UPI | I13: 1.3 | J13: April | K13: 2024 | L13: 48780.78 | M13: 15 | N13: Retail | O13: South
... A1001: ORD01000 | B1001: Table Lamp | C1001: Home & Kitchen | D1001: 16698.12 | E1001: 4 | F1001: 66792.48 | G1001: 45377 | H1001: Credit Card | I1001: 1.6 | J1001: March | K1001: 2024 | L1001: 13358.496 | M1001: 19 | N1001: Wholesale | O1001: East
